Workbook

Sheet README
A1: X (Super Intellect) — Round 1 Financial Model
A3: Purpose | B3: Stage-gated financial model for the ₹180 Cr Round 1 at ₹6,000 Cr post-money (3.0%). Built for explaining the opportunity, the use of funds, the return profile and the investor protections to Indian angel / family-office / strategic investors.
A4: Basis | B4: Frozen Core 1.0 (X_Final_Canon, 2 Sep 2026, slides 1–80): X = Interpretive Intelligence activated through Cognitive Continuity; product object = Portable Cognitive Identity; architecture = XOS. The extract provided contains no XOS architecture detail, proof plan or commercial plan, so all cost, timing and outcome numbers here are PROPOSED ASSUMPTIONS, not derived from the Canon.
A5: Colour code | B5: Blue text = hard-coded input you can change. Black = formula. Green = link from another sheet. Yellow fill = key assumption to review first.
A6: Truthiness | B6: Each key assumption carries an epistemic state using the Canon vocabulary (Known / Demonstrated / Inferred / Assumed / Uncertain / Disputed). See the Truthiness_Ledger sheet for claim, limit, counter-lens and falsifier.
A7: Sheets | B7: Inputs · Round_CapTable · Use_of_Funds · Burn_Plan · Stage_Plan · Returns · Valuation · Truthiness_Ledger · Checks
A8: Start here | B8: 1) Inputs: confirm FX, round terms, tranches, scenario probabilities. 2) Burn_Plan: replace headcount/cost ramps with the real plan. 3) Inputs!B17: enter the founder allocation (currently 0 = TBD). 4) Checks: everything must read OK.
A9: Unit | B9: ₹ Crore unless stated. 1 Cr = 10 million. USD figures use the FX input (Assumption, update to the prevailing rate).
A10: Important | B10: Scenario probabilities and exit values are illustrative judgement calls, not forecasts. Investors will bring their own; the model is built so they can change them. Market comparables are press-reported, not company-confirmed. This is a planning model, not investment, legal or tax advice — have counsel and a chartered accountant validate structure (SEBI, FEMA, Companies Act, tax).

Sheet Inputs
A1: Inputs & Assumptions
A2: Blue = input. Epistemic state uses the Canon Truthiness vocabulary. All ₹ in Crore.
A4: Assumption | B4: Value | C4: Unit | D4: Epistemic state | E4: Source / note
A5: Round terms
A6: FX rate | B6: 90 | C6: ₹ per US$ | D6: ASSUMED | E6: Placeholder — update to prevailing rate.
A7: Post-money valuation | B7: 6000 | C7: ₹ Cr | D7: FOUNDER-SET | E7: Founder instruction: ₹6,000 Cr valuation.
A8: Round 1 size | B8: 180 | C8: ₹ Cr | D8: FOUNDER-SET | E8: Founder instruction: ₹180 Cr (≈3%).
A9: Pre-money valuation | B9: =B7-B8 -> 5820 | C9: ₹ Cr | E9: Post-money less round size.
A10: New-investor dilution | B10: =SUMPRODUCT(E23:E26/I23:I26) -> 0.03 | C10: % | E10: Σ tranche ÷ tranche post-money (= round ÷ post-money when priced flat).
A11: Price of 1% of the company | B11: =B7/100 -> 60 | C11: ₹ Cr
A12: Post-money in US$ | B12: =B7*10/B6 -> 666.66667 | C12: US$ mn | E12: ₹ Cr × 10 ÷ FX.
A13: Round size in US$ | B13: =B8*10/B6 -> 20 | C13: US$ mn
A14: Investor hurdle rate | B14: 0.3 | C14: % p.a. | D14: ASSUMED | E14: Typical early-stage Indian angel/VC hurdle; investors will set their own.
A15: Minimum contingency reserve | B15: 0.1 | C15: % of round | D15: ASSUMED | E15: Policy floor for unallocated reserve.
A16: GPU cost | B16: 100 | C16: ₹ / GPU-hr | D16: ASSUMED | E16: IndiaAI-reported subsidised rates ≈ ₹65–116/GPU-hr (press-reported); open-market rates are higher. Update with quotes.
A17: Founder allocation within round | B17: 0 | C17: ₹ Cr | D17: TBD | E17: Founder said "my part" will follow. Placeholder = 0; any amount reduces the reserve. Recommend a capped, disclosed amount.
A18: Founders — pre-round ownership | B18: 0.85 | C18: % | D18: TBD | E18: Placeholder; replace with actual cap table.
A19: ESOP pool — pre-round | B19: 0.1 | C19: % | D19: TBD | E19: Placeholder.
A20: Other holders — pre-round | B20: 0.05 | C20: % | D20: TBD | E20: Placeholder.
A21: SEBI angel-fund cap per startup | B21: 25 | C21: ₹ Cr | D21: INFERRED | E21: SEBI board approved ₹10 lakh–₹25 Cr per startup (June 2025, press/law-firm summaries). Verify final notification.
A22: Tranche | B22: % of round | C22: Release qtr | D22: Timing (yrs) | E22: Amount (₹ Cr) | F22: Cumulative (₹ Cr) | G22: Gate / milestone (PROPOSED — define with counsel and Scientific Advisory Board) | H22: Idx | I22: Post-money for tranche (₹ Cr)
A23: T1 — Closing | B23: 0.25 | C23: 1 | D23: =(C23-1)/4 -> 0 | E23: =B23*$B$8 -> 45 | F23: =SUM($E$23:E23) -> 45 | G23: Close. Fund build of the reference implementation of Portable Cognitive Identity (8 layers) and the Continuity Handshake. | H23: 1 | I23: =$B$7 -> 6000 | J23: Default = flat headline price. Override I23:I26 with step prices (e.g. 3000 / 4500 / 6000 / 6000) to test a milestone-earned valuation; dilution then rises above 3%.
A24: T2 — Gate 1 (Proof) | B24: 0.25 | C24: 5 | D24: =(C24-1)/4 -> 1 | E24: =B24*$B$8 -> 45 | F24: =SUM($E$23:E24) -> 90 | G24: Reference implementation live across ≥3 model families; independent validation report on calibrated-claims benchmark; ≥2 design-partner pilots signed. | H24: 2 | I24: =$B$7 -> 6000
A25: T3 — Gate 2 (Demand + Co-Creator) | B25: 0.25 | C25: 9 | D25: =(C25-1)/4 -> 2 | E25: =B25*$B$8 -> 45 | F25: =SUM($E$23:E25) -> 135 | G25: ≥5 paid pilots/LOIs; security certification (e.g. ISO 27001) achieved; signed LOI / term sheet from ≥1 Co-Creator candidate. | H25: 3 | I25: =$B$7 -> 6000
A26: T4 — Gate 3 (Co-Creation) | B26: 0.25 | C26: 13 | D26: =(C26-1)/4 -> 3 | E26: =B26*$B$8 -> 45 | F26: =SUM($E$23:E26) -> 180 | G26: Definitive co-creation / option agreement with Co-Creator (exclusivity fee received) or strategic licence executed. | H26: 4 | I26: =$B$7 -> 6000
A27: Total / check | B27: =SUM(B23:B26) -> 1 | E27: =SUM(E23:E26) -> 180
A29: Scenario | B29: Type (S=success, F=fail) | C29: Probability | D29: Company equity value at event (₹ Cr) | E29: Additional dilution before exit | F29: Tranches deployed | G29: Avg hold (yrs) | H29: Liq. pref (x) | I29: Recovery % of invested (fail cases) | J29: Rationale / precedent
A30: S1 Co-creation: X becomes the continuity layer in the Co-Creator platform / JV | B30: S | C30: 0.05 | D30: 90000 | E30: 0.3 | F30: 4 | G30: 6 | H30: 1 | I30: 0 | J30: ≈US$10B at FX 90. Below SSI (~US$32B, pre-product). Requires broad adoption as infrastructure layer.
A31: S2 IP / platform sale or exclusive licence to Co-Creator | B31: S | C31: 0.1 | D31: 30000 | E31: 0.15 | F31: 4 | G31: 5 | H31: 1 | I31: 0 | J31: ≈US$3.3B. Same order as Google–Character.AI licence (~US$2.7B, press-reported).
A32: S3 Partial: non-exclusive licence + team/IP transfer | B32: S | C32: 0.15 | D32: 6000 | E32: 0.1 | F32: 4 | G32: 4 | H32: 1 | I32: 0 | J32: ≈US$0.67B. Same order as Microsoft–Inflection (~US$0.65B, press-reported). Pref protects capital.
A33: S4 Stops after Gate 3 not met (T4 never released) | B33: F | C33: 0.1 | D33: 0 | E33: 0 | F33: 3 | G33: 3 | H33: 1 | I33: 0.2 | J33: Wind-down / IP salvage; unspent cash + IP residual.
A34: S5 Stops at Gate 2 (T3 never released) | B34: F | C34: 0.25 | D34: 0 | E34: 0 | F34: 2 | G34: 2 | H34: 1 | I34: 0.25 | J34: Fails to convert pilots/Co-Creator interest.
A35: S6 Stops at Gate 1 (T2 never released) | B35: F | C35: 0.35 | D35: 0 | E35: 0 | F35: 1 | G35: 1 | H35: 1 | I35: 0.3 | J35: Reference implementation or validation fails.
A36: Probability total | C36: =SUM(C30:C35) -> 1
A37: Probabilities are illustrative judgement (state: ASSUMED). They are NOT derived from the Frozen Core.

Sheet Round_CapTable
A1: Round Structure & Cap Table
A2: Pre/post ownership uses placeholder pre-round holdings (Inputs). Syndicate tickets are illustrative inputs.
A4: Holder | B4: Pre-round % | C4: Post-round % | D4: Value at post-money (₹ Cr)
A5: Founders | B5: =Inputs!B18 -> 0.85 | C5: =B5*(1-Inputs!$B$10) -> 0.8245 | D5: =C5*Inputs!$B$7 -> 4947
A6: ESOP pool | B6: =Inputs!B19 -> 0.1 | C6: =B6*(1-Inputs!$B$10) -> 0.097 | D6: =C6*Inputs!$B$7 -> 582
A7: Other holders | B7: =Inputs!B20 -> 0.05 | C7: =B7*(1-Inputs!$B$10) -> 0.0485 | D7: =C7*Inputs!$B$7 -> 291
A8: Round 1 investors (new) | B8: 0 | C8: =Inputs!B10 -> 0.03 | D8: =C8*Inputs!$B$7 -> 180
A9: Total | B9: =SUM(B5:B8) -> 1 | C9: =SUM(C5:C8) -> 1 | D9: =C9*Inputs!$B$7 -> 6000
A11: Illustrative syndicate (₹180 Cr cannot come from angels alone)
A12: Investor class | B12: Ticket (₹ Cr) | C12: Post-round % | D12: T1 (₹ Cr) | E12: T2 | F12: T3 | G12: Note
A13: Lead investor (family office / strategic / Cat II AIF) | B13: 60 | C13: =B13/Inputs!$B$7 -> 0.01 | D13: =$B13*Inputs!$B$23 -> 15 | E13: =$B13*Inputs!$B$24 -> 15 | F13: =$B13*Inputs!$B$25 -> 15 | G13: Sets terms; takes board seat.
A14: Anchor 1 (UHNI / family office) | B14: 25 | C14: =B14/Inputs!$B$7 -> 0.0041666667 | D14: =$B14*Inputs!$B$23 -> 6.25 | E14: =$B14*Inputs!$B$24 -> 6.25 | F14: =$B14*Inputs!$B$25 -> 6.25
A15: Anchor 2 (UHNI / family office) | B15: 25 | C15: =B15/Inputs!$B$7 -> 0.0041666667 | D15: =$B15*Inputs!$B$23 -> 6.25 | E15: =$B15*Inputs!$B$24 -> 6.25 | F15: =$B15*Inputs!$B$25 -> 6.25
A16: Anchor 3 (strategic / corporate) | B16: 20 | C16: =B16/Inputs!$B$7 -> 0.0033333333 | D16: =$B16*Inputs!$B$23 -> 5 | E16: =$B16*Inputs!$B$24 -> 5 | F16: =$B16*Inputs!$B$25 -> 5
A17: Family-office & UHNI pool | B17: 30 | C17: =B17/Inputs!$B$7 -> 0.005 | D17: =$B17*Inputs!$B$23 -> 7.5 | E17: =$B17*Inputs!$B$24 -> 7.5 | F17: =$B17*Inputs!$B$25 -> 7.5 | G17: Private placement ≤200 persons per FY — confirm with counsel.
A18: Angel funds / accredited-investor syndicate | B18: 20 | C18: =B18/Inputs!$B$7 -> 0.0033333333 | D18: =$B18*Inputs!$B$23 -> 5 | E18: =$B18*Inputs!$B$24 -> 5 | F18: =$B18*Inputs!$B$25 -> 5 | G18: SEBI angel-fund cap per startup applies per fund (Inputs!B21).
A19: Total | B19: =SUM(B13:B18) -> 180 | C19: =SUM(C13:C18) -> 0.03 | D19: =SUM(D13:D18) -> 45 | E19: =SUM(E13:E18) -> 45 | F19: =SUM(F13:F18) -> 45
A21: Max a single angel fund can write (₹ Cr) | B21: =Inputs!B21 -> 25 | G21: ⇒ A lead + anchors are structurally required; angel funds fill the tail.
A22: …as % of the round | B22: =B21/Inputs!B8 -> 0.13888889
A24: Note: T4 column omitted for width; T4 = Ticket × Inputs!B26.

Sheet Use_of_Funds
A1: Utilisation of Round 1 Funds
A2: Programme lines are linked from Burn_Plan; reserve is the balance after founder allocation.
A4: Category | B4: ₹ Cr | C4: % of round | D4: US$ mn | E4: What it buys / investor-visible output
A5: People — research, platform, trust, product, pilots, ops | B5: =Burn_Plan!S24 -> 82.685 | C5: =B5/Inputs!$B$8 -> 0.45936111 | D5: =B5*10/Inputs!$B$6 -> 9.1872222 | E5: Core team that builds the reference implementation of Portable Cognitive Identity and the Continuity Handshake; headcount in Burn_Plan.
A6: Compute | B6: =Burn_Plan!S28 -> 12.4 | C6: =B6/Inputs!$B$8 -> 0.068888889 | D6: =B6*10/Inputs!$B$6 -> 1.3777778 | E6: Training/fine-tuning/evaluation experiments across model families (model-agnostic by Canon design).
A7: Model API & evaluation | B7: =Burn_Plan!S31 -> 6.2 | C7: =B7/Inputs!$B$8 -> 0.034444444 | D7: =B7*10/Inputs!$B$6 -> 0.68888889 | E7: Cross-model testing so portability is demonstrated, not claimed.
A8: Independent validation, SAB & red-team | B8: =Burn_Plan!S32 -> 8.5 | C8: =B8/Inputs!$B$8 -> 0.047222222 | D8: =B8*10/Inputs!$B$6 -> 0.94444444 | E8: Third-party proof of Interpretive Calibration; Scientific Advisory Board; Truthiness audit. Releases T2.
A9: Security, privacy & trust certification | B9: =Burn_Plan!S33 -> 9.1 | C9: =B9/Inputs!$B$8 -> 0.050555556 | D9: =B9*10/Inputs!$B$6 -> 1.0111111 | E9: ISO 27001-class certification, pen-tests, key management; consent/permission map built to India DPDP Act 2023 principles (counsel to confirm).
A10: IP & standards | B10: =Burn_Plan!S34 -> 6.5 | C10: =B10/Inputs!$B$8 -> 0.036111111 | D10: =B10*10/Inputs!$B$6 -> 0.72222222 | E10: Patents, trademarks, open specification and standards-body participation; protects the exit asset.
A11: Pilots & design partners | B11: =Burn_Plan!S35 -> 14.7 | C11: =B11/Inputs!$B$8 -> 0.081666667 | D11: =B11*10/Inputs!$B$6 -> 1.6333333 | E11: Enterprise / government / device pilots; converts thesis into paid evidence. Releases T3.
A12: Co-Creator search & transaction advisory | B12: =Burn_Plan!S36 -> 7.1 | C12: =B12/Inputs!$B$8 -> 0.039444444 | D12: =B12*10/Inputs!$B$6 -> 0.78888889 | E12: Banker / advisory, data-room, legal for the Stage 2 process. Releases T4.
A13: Governance, legal & audit | B13: =Burn_Plan!S37 -> 3.2 | C13: =B13/Inputs!$B$8 -> 0.017777778 | D13: =B13*10/Inputs!$B$6 -> 0.35555556 | E13: Board, statutory audit, investor reporting, escrow and compliance.
A14: Facilities & tooling | B14: =Burn_Plan!S38 -> 6.85 | C14: =B14/Inputs!$B$8 -> 0.038055556 | D14: =B14*10/Inputs!$B$6 -> 0.76111111 | E14: Office, security tooling, developer infrastructure.
A15: Frontier research option (incl. quantum exploration) | B15: =Burn_Plan!S39 -> 3.5 | C15: =B15/Inputs!$B$8 -> 0.019444444 | D15: =B15*10/Inputs!$B$6 -> 0.38888889 | E15: Small option on long-horizon work toward the Super Intellect horizon; state UNCERTAIN, not required for Stages 1–2.
A16: Founder allocation (TBD) | B16: =Inputs!B17 -> 0 | C16: =B16/Inputs!$B$8 -> 0 | D16: =B16*10/Inputs!$B$6 -> 0 | E16: Placeholder pending founder input; recommend capped and disclosed to investors.
A17: Contingency reserve (balance) | B17: =Inputs!B8-SUM(B5:B16) -> 19.265 | C17: =B17/Inputs!$B$8 -> 0.10702778 | D17: =B17*10/Inputs!$B$6 -> 2.1405556 | E17: Held for slippage, extension of runway, or Gate 3 transaction costs. Must be ≥ policy floor (Inputs!B15).
A18: TOTAL | B18: =SUM(B5:B17) -> 180 | C18: =SUM(C5:C17) -> 1 | D18: =SUM(D5:D17) -> 20
A20: Each tranche funds a defined stage window (spend between releases)
A21: Window | B21: Tranche received (₹ Cr) | C21: Spend in window (₹ Cr) | D21: Surplus / (shortfall) | E21: Note
A22: =Inputs!A23 -> T1 — Closing | B22: =Inputs!E23 -> 45 | C22: =SUMIFS(Burn_Plan!$C$41:$R$41,Burn_Plan!$C$4:$R$4,">="&Inputs!C23,Burn_Plan!$C$4:$R$4,"<"&Inputs!C24) -> 29.635 | D22: =B22-C22 -> 15.365 | E22: Window = from this release quarter until the next. Surpluses carry forward as buffer.
A23: =Inputs!A24 -> T2 — Gate 1 (Proof) | B23: =Inputs!E24 -> 45 | C23: =SUMIFS(Burn_Plan!$C$41:$R$41,Burn_Plan!$C$4:$R$4,">="&Inputs!C24,Burn_Plan!$C$4:$R$4,"<"&Inputs!C25) -> 47 | D23: =B23-C23 -> -2
A24: =Inputs!A25 -> T3 — Gate 2 (Demand + Co-Creator) | B24: =Inputs!E25 -> 45 | C24: =SUMIFS(Burn_Plan!$C$41:$R$41,Burn_Plan!$C$4:$R$4,">="&Inputs!C25,Burn_Plan!$C$4:$R$4,"<"&Inputs!C26) -> 45.46 | D24: =B24-C24 -> -0.46
A25: =Inputs!A26 -> T4 — Gate 3 (Co-Creation) | B25: =Inputs!E26 -> 45 | C25: =SUMIFS(Burn_Plan!$C$41:$R$41,Burn_Plan!$C$4:$R$4,">="&Inputs!C26,Burn_Plan!$C$4:$R$4,"<"&99) -> 38.64 | D25: =B25-C25 -> 6.36
A26: Total | B26: =SUM(B22:B25) -> 180 | C26: =SUM(C22:C25) -> 160.735 | D26: =SUM(D22:D25) -> 19.265

Sheet Burn_Plan
A1: Quarterly Burn Plan — 16 quarters (4 years)
A2: Proposed ramp (ASSUMED). Replace headcount and cost rows with the real plan. Cost per head in column B is loaded annual ₹ lakh.
A4: Line item | B4: Loaded cost / rate | C4: 1 | D4: 2 | E4: 3 | F4: 4 | G4: 5 | H4: 6 | I4: 7 | J4: 8 | K4: 9 | L4: 10 | M4: 11 | N4: 12 | O4: 13 | P4: 14 | Q4: 15 | R4: 16 | S4: Total
A5: Plan year | C5: =INT((C4-1)/4)+1 -> 1 | D5: =INT((D4-1)/4)+1 -> 1 | E5: =INT((E4-1)/4)+1 -> 1 | F5: =INT((F4-1)/4)+1 -> 1 | G5: =INT((G4-1)/4)+1 -> 2 | H5: =INT((H4-1)/4)+1 -> 2 | I5: =INT((I4-1)/4)+1 -> 2 | J5: =INT((J4-1)/4)+1 -> 2 | ... R5: =INT((R4-1)/4)+1 -> 4
A7: Headcount (end of quarter)
A8: Principal investigators / fellows | B8: 150 | C8: 2 | D8: 3 | E8: 3 | F8: 3 | G8: 3 | H8: 3 | I8: 3 | J8: 3 | K8: 3 | L8: 3 | M8: 3 | N8: 3 | O8: 3 | P8: 3 | Q8: 3 | R8: 3
A9: Research scientists (interpretation, epistemics, learning) | B9: 60 | C9: 3 | D9: 4 | E9: 5 | F9: 6 | G9: 6 | H9: 6 | I9: 6 | J9: 6 | K9: 6 | L9: 6 | M9: 6 | N9: 6 | O9: 6 | P9: 6 | Q9: 6 | R9: 6
A10: Platform & ML engineers | B10: 42 | C10: 4 | D10: 7 | E10: 10 | F10: 12 | G10: 14 | H10: 15 | I10: 15 | J10: 15 | K10: 15 | L10: 15 | M10: 15 | N10: 15 | O10: 14 | P10: 14 | Q10: 14 | R10: 14
A11: Security, privacy & trust engineers | B11: 50 | C11: 2 | D11: 3 | E11: 4 | F11: 4 | G11: 5 | H11: 5 | I11: 5 | J11: 5 | K11: 5 | L11: 5 | M11: 5 | N11: 5 | O11: 5 | P11: 5 | Q11: 5 | R11: 5
A12: Product & design | B12: 40 | C12: 2 | D12: 3 | E12: 3 | F12: 4 | G12: 4 | H12: 5 | I12: 5 | J12: 5 | K12: 5 | L12: 5 | M12: 5 | N12: 5 | O12: 5 | P12: 5 | Q12: 5 | R12: 5
A13: Enterprise pilots & solutions | B13: 38 | C13: 0 | D13: 1 | E13: 2 | F13: 3 | G13: 4 | H13: 6 | I13: 7 | J13: 7 | K13: 7 | L13: 7 | M13: 7 | N13: 7 | O13: 7 | P13: 7 | Q13: 7 | R13: 7
A14: Ops, legal & finance | B14: 30 | C14: 2 | D14: 3 | E14: 3 | F14: 4 | G14: 4 | H14: 5 | I14: 5 | J14: 5 | K14: 5 | L14: 5 | M14: 5 | N14: 5 | O14: 5 | P14: 5 | Q14: 5 | R14: 5
A15: Total headcount | C15: =SUM(C8:C14) -> 15 | D15: =SUM(D8:D14) -> 24 | E15: =SUM(E8:E14) -> 30 | F15: =SUM(F8:F14) -> 36 | G15: =SUM(G8:G14) -> 40 | H15: =SUM(H8:H14) -> 45 | I15: =SUM(I8:I14) -> 46 | J15: =SUM(J8:J14) -> 46 | ... R15: =SUM(R8:R14) -> 45
A16: People cost (₹ Cr) = headcount × annual ₹ lakh ÷ 4 ÷ 100
A17: Principal investigators / fellows | C17: =C8*$B8/400 -> 0.75 | D17: =D8*$B8/400 -> 1.125 | E17: =E8*$B8/400 -> 1.125 | F17: =F8*$B8/400 -> 1.125 | G17: =G8*$B8/400 -> 1.125 | H17: =H8*$B8/400 -> 1.125 | I17: =I8*$B8/400 -> 1.125 | J17: =J8*$B8/400 -> 1.125 | ... R17: =R8*$B8/400 -> 1.125 | S17: =SUM(C17:R17) -> 17.625
A18: Research scientists (interpretation, epistemics, learning) | C18: =C9*$B9/400 -> 0.45 | D18: =D9*$B9/400 -> 0.6 | E18: =E9*$B9/400 -> 0.75 | F18: =F9*$B9/400 -> 0.9 | G18: =G9*$B9/400 -> 0.9 | H18: =H9*$B9/400 -> 0.9 | I18: =I9*$B9/400 -> 0.9 | J18: =J9*$B9/400 -> 0.9 | ... R18: =R9*$B9/400 -> 0.9 | S18: =SUM(C18:R18) -> 13.5
A19: Platform & ML engineers | C19: =C10*$B10/400 -> 0.42 | D19: =D10*$B10/400 -> 0.735 | E19: =E10*$B10/400 -> 1.05 | F19: =F10*$B10/400 -> 1.26 | G19: =G10*$B10/400 -> 1.47 | H19: =H10*$B10/400 -> 1.575 | I19: =I10*$B10/400 -> 1.575 | J19: =J10*$B10/400 -> 1.575 | ... R19: =R10*$B10/400 -> 1.47 | S19: =SUM(C19:R19) -> 21.84
A20: Security, privacy & trust engineers | C20: =C11*$B11/400 -> 0.25 | D20: =D11*$B11/400 -> 0.375 | E20: =E11*$B11/400 -> 0.5 | F20: =F11*$B11/400 -> 0.5 | G20: =G11*$B11/400 -> 0.625 | H20: =H11*$B11/400 -> 0.625 | I20: =I11*$B11/400 -> 0.625 | J20: =J11*$B11/400 -> 0.625 | ... R20: =R11*$B11/400 -> 0.625 | S20: =SUM(C20:R20) -> 9.125
A21: Product & design | C21: =C12*$B12/400 -> 0.2 | D21: =D12*$B12/400 -> 0.3 | E21: =E12*$B12/400 -> 0.3 | F21: =F12*$B12/400 -> 0.4 | G21: =G12*$B12/400 -> 0.4 | H21: =H12*$B12/400 -> 0.5 | I21: =I12*$B12/400 -> 0.5 | J21: =J12*$B12/400 -> 0.5 | ... R21: =R12*$B12/400 -> 0.5 | S21: =SUM(C21:R21) -> 7.1
A22: Enterprise pilots & solutions | C22: =C13*$B13/400 -> 0 | D22: =D13*$B13/400 -> 0.095 | E22: =E13*$B13/400 -> 0.19 | F22: =F13*$B13/400 -> 0.285 | G22: =G13*$B13/400 -> 0.38 | H22: =H13*$B13/400 -> 0.57 | I22: =I13*$B13/400 -> 0.665 | J22: =J13*$B13/400 -> 0.665 | ... R22: =R13*$B13/400 -> 0.665 | S22: =SUM(C22:R22) -> 8.17
A23: Ops, legal & finance | C23: =C14*$B14/400 -> 0.15 | D23: =D14*$B14/400 -> 0.225 | E23: =E14*$B14/400 -> 0.225 | F23: =F14*$B14/400 -> 0.3 | G23: =G14*$B14/400 -> 0.3 | H23: =H14*$B14/400 -> 0.375 | I23: =I14*$B14/400 -> 0.375 | J23: =J14*$B14/400 -> 0.375 | ... R23: =R14*$B14/400 -> 0.375 | S23: =SUM(C23:R23) -> 5.325
A24: People total | C24: =SUM(C17:C23) -> 2.22 | D24: =SUM(D17:D23) -> 3.455 | E24: =SUM(E17:E23) -> 4.14 | F24: =SUM(F17:F23) -> 4.77 | G24: =SUM(G17:G23) -> 5.2 | H24: =SUM(H17:H23) -> 5.67 | I24: =SUM(I17:I23) -> 5.765 | J24: =SUM(J17:J23) -> 5.765 | ... S24: =SUM(S17:S23) -> 82.685
A26: Compute
A27: GPU-hours (thousand) | B27: =Inputs!B16 -> 100 | C27: 20 | D27: 40 | E27: 60 | F27: 80 | G27: 100 | H27: 100 | I27: 100 | J27: 100 | K27: 100 | L27: 100 | M27: 100 | N27: 100 | O27: 60 | P27: 60 | Q27: 60 | R27: 60 | S27: =SUM(C27:R27) -> 1240
A28: Compute cost (₹ Cr) | C28: =C27*$B$27/10000 -> 0.2 | D28: =D27*$B$27/10000 -> 0.4 | E28: =E27*$B$27/10000 -> 0.6 | F28: =F27*$B$27/10000 -> 0.8 | G28: =G27*$B$27/10000 -> 1 | H28: =H27*$B$27/10000 -> 1 | I28: =I27*$B$27/10000 -> 1 | J28: =J27*$B$27/10000 -> 1 | ... R28: =R27*$B$27/10000 -> 0.6 | S28: =SUM(C28:R28) -> 12.4
A30: Other programme costs (₹ Cr)
A31: Model API & evaluation (multi-model) | C31: 0.2 | D31: 0.3 | E31: 0.4 | F31: 0.5 | G31: 0.5 | H31: 0.5 | I31: 0.5 | J31: 0.5 | K31: 0.4 | L31: 0.4 | M31: 0.4 | N31: 0.4 | O31: 0.3 | P31: 0.3 | Q31: 0.3 | R31: 0.3 | S31: =SUM(C31:R31) -> 6.2
A32: Independent validation, SAB & red-team | C32: 0.3 | D32: 0.5 | E32: 0.7 | F32: 0.9 | G32: 0.7 | H32: 0.6 | I32: 0.6 | J32: 0.6 | K32: 0.5 | L32: 0.5 | M32: 0.5 | N32: 0.5 | O32: 0.4 | P32: 0.4 | Q32: 0.4 | R32: 0.4 | S32: =SUM(C32:R32) -> 8.5
A33: Security, privacy & trust certification | C33: 0.3 | D33: 0.4 | E33: 0.5 | F33: 0.7 | G33: 0.7 | H33: 0.7 | I33: 0.7 | J33: 0.7 | K33: 0.6 | L33: 0.6 | M33: 0.6 | N33: 0.6 | O33: 0.5 | P33: 0.5 | Q33: 0.5 | R33: 0.5 | S33: =SUM(C33:R33) -> 9.1
A34: IP & standards (patents, spec, standards bodies) | C34: 0.6 | D34: 0.5 | E34: 0.5 | F34: 0.5 | G34: 0.4 | H34: 0.4 | I34: 0.4 | J34: 0.4 | K34: 0.4 | L34: 0.4 | M34: 0.4 | N34: 0.4 | O34: 0.3 | P34: 0.3 | Q34: 0.3 | R34: 0.3 | S34: =SUM(C34:R34) -> 6.5
A35: Pilots & design partners (integration, travel, infra) | C35: 0 | D35: 0.3 | E35: 0.6 | F35: 1 | G35: 1.2 | H35: 1.2 | I35: 1.2 | J35: 1.2 | K35: 1.2 | L35: 1.2 | M35: 1.2 | N35: 1.2 | O35: 0.8 | P35: 0.8 | Q35: 0.8 | R35: 0.8 | S35: =SUM(C35:R35) -> 14.7
A36: Co-Creator search & transaction advisory | C36: 0.1 | D36: 0.2 | E36: 0.3 | F36: 0.4 | G36: 0.6 | H36: 0.7 | I36: 0.8 | J36: 0.8 | K36: 0.6 | L36: 0.5 | M36: 0.5 | N36: 0.4 | O36: 0.3 | P36: 0.3 | Q36: 0.3 | R36: 0.3 | S36: =SUM(C36:R36) -> 7.1
A37: Governance, legal & audit | C37: 0.2 | D37: 0.2 | E37: 0.2 | F37: 0.2 | G37: 0.2 | H37: 0.2 | I37: 0.2 | J37: 0.2 | K37: 0.2 | L37: 0.2 | M37: 0.2 | N37: 0.2 | O37: 0.2 | P37: 0.2 | Q37: 0.2 | R37: 0.2 | S37: =SUM(C37:R37) -> 3.2
A38: Facilities & tooling | C38: 0.2 | D38: 0.3 | E38: 0.35 | F38: 0.4 | G38: 0.5 | H38: 0.5 | I38: 0.5 | J38: 0.5 | K38: 0.5 | L38: 0.5 | M38: 0.5 | N38: 0.5 | O38: 0.4 | P38: 0.4 | Q38: 0.4 | R38: 0.4 | S38: =SUM(C38:R38) -> 6.85
A39: Frontier research option (incl. quantum exploration) | C39: 0 | D39: 0 | E39: 0.1 | F39: 0.2 | G39: 0.3 | H39: 0.3 | I39: 0.3 | J39: 0.3 | K39: 0.3 | L39: 0.3 | M39: 0.3 | N39: 0.3 | O39: 0.2 | P39: 0.2 | Q39: 0.2 | R39: 0.2 | S39: =SUM(C39:R39) -> 3.5
A41: TOTAL PROGRAMME SPEND (₹ Cr) | C41: =C24+C28+SUM(C31:C39) -> 4.32 | D41: =D24+D28+SUM(D31:D39) -> 6.555 | E41: =E24+E28+SUM(E31:E39) -> 8.39 | F41: =F24+F28+SUM(F31:F39) -> 10.37 | G41: =G24+G28+SUM(G31:G39) -> 11.3 | H41: =H24+H28+SUM(H31:H39) -> 11.77 | I41: =I24+I28+SUM(I31:I39) -> 11.965 | J41: =J24+J28+SUM(J31:J39) -> 11.965 | ... S41: =S24+S28+SUM(S31:S39) -> 160.735
A43: Cash from the round only (excludes any revenue)
A44: Tranche received (₹ Cr) | C44: =SUMIF(Inputs!$C$23:$C$26,C$4,Inputs!$E$23:$E$26) -> 45 | D44: =SUMIF(Inputs!$C$23:$C$26,D$4,Inputs!$E$23:$E$26) -> 0 | E44: =SUMIF(Inputs!$C$23:$C$26,E$4,Inputs!$E$23:$E$26) -> 0 | F44: =SUMIF(Inputs!$C$23:$C$26,F$4,Inputs!$E$23:$E$26) -> 0 | G44: =SUMIF(Inputs!$C$23:$C$26,G$4,Inputs!$E$23:$E$26) -> 45 | H44: =SUMIF(Inputs!$C$23:$C$26,H$4,Inputs!$E$23:$E$26) -> 0 | I44: =SUMIF(Inputs!$C$23:$C$26,I$4,Inputs!$E$23:$E$26) -> 0 | J44: =SUMIF(Inputs!$C$23:$C$26,J$4,Inputs!$E$23:$E$26) -> 0 | ... R44: =SUMIF(Inputs!$C$23:$C$26,R$4,Inputs!$E$23:$E$26) -> 0 | S44: =SUM(C44:R44) -> 180
A45: Opening cash | C45: 0 | D45: =C46 -> 40.68 | E45: =D46 -> 34.125 | F45: =E46 -> 25.735 | G45: =F46 -> 15.365 | H45: =G46 -> 49.065 | I45: =H46 -> 37.295 | J45: =I46 -> 25.33 | K45: =J46 -> 13.365 | ... R45: =Q46 -> 28.925
A46: Closing cash | C46: =C45+C44-C41 -> 40.68 | D46: =D45+D44-D41 -> 34.125 | E46: =E45+E44-E41 -> 25.735 | F46: =F45+F44-F41 -> 15.365 | G46: =G45+G44-G41 -> 49.065 | H46: =H45+H44-H41 -> 37.295 | I46: =I45+I44-I41 -> 25.33 | J46: =J45+J44-J41 -> 13.365 | ... R46: =R45+R44-R41 -> 19.265
...

Sheet Stage_Plan
A1: Stage Plan — Company cash view (annual)
A2: Three stages per founder roadmap. Revenue / other inflows are ASSUMED and are NOT used in investor-return calcs (Returns sheet).
A4: ₹ Cr | B4: Y1 | C4: Y2 | D4: Y3 | E4: Y4 | F4: Y5 | G4: Y6 | H4: Total | I4: Note
A5: Stage | B5: 1: Monetise concept (3%) | C5: 1→2 | D5: 2: Find Co-Creator | E5: 2→3 | F5: 3: Build / Exit | G5: 3: Build / Exit
A6: Plan year index | B6: 1 | C6: 2 | D6: 3 | E6: 4 | F6: 5 | G6: 6
A7: Inflows
A8: Round 1 tranches received | B8: =SUMPRODUCT((INT((Inputs!$C$23:$C$26-1)/4)+1=B$6)*Inputs!$E$23:$E$26) -> 45 | C8: =SUMPRODUCT((INT((Inputs!$C$23:$C$26-1)/4)+1=C$6)*Inputs!$E$23:$E$26) -> 45 | D8: =SUMPRODUCT((INT((Inputs!$C$23:$C$26-1)/4)+1=D$6)*Inputs!$E$23:$E$26) -> 45 | E8: =SUMPRODUCT((INT((Inputs!$C$23:$C$26-1)/4)+1=E$6)*Inputs!$E$23:$E$26) -> 45 | F8: =SUMPRODUCT((INT((Inputs!$C$23:$C$26-1)/4)+1=F$6)*Inputs!$E$23:$E$26) -> 0 | G8: =SUMPRODUCT((INT((Inputs!$C$23:$C$26-1)/4)+1=G$6)*Inputs!$E$23:$E$26) -> 0 | H8: =SUM(B8:G8) -> 180
A9: Pilot / design-partner / licence revenue (ASSUMED) | B9: 0 | C9: 3 | D9: 12 | E9: 30 | F9: 40 | G9: 50 | H9: =SUM(B9:G9) -> 135 | I9: Illustrative: pilots × fee. State: ASSUMED until LOIs exist.
A10: Government / research grants (ASSUMED) | B10: 0 | C10: 2 | D10: 2 | E10: 0 | F10: 0 | G10: 0 | H10: =SUM(B10:G10) -> 4 | I10: Illustrative.
A11: Co-Creator exclusivity / option fee (ASSUMED) | B11: 0 | C11: 0 | D11: 0 | E11: 25 | F11: 0 | G11: 0 | H11: =SUM(B11:G11) -> 25 | I11: Illustrative; part of Stage 2 negotiation.
A12: Co-Creator cost-share of joint build (ASSUMED) | B12: 0 | C12: 0 | D12: 0 | E12: 0 | F12: 30 | G12: 30 | H12: =SUM(B12:G12) -> 60 | I12: Stage 3 only.
A13: Total inflows | B13: =SUM(B8:B12) -> 45 | C13: =SUM(C8:C12) -> 50 | D13: =SUM(D8:D12) -> 59 | E13: =SUM(E8:E12) -> 100 | F13: =SUM(F8:F12) -> 70 | G13: =SUM(G8:G12) -> 80 | H13: =SUM(B13:G13) -> 404
A14: Outflows
A15: Programme spend (from Burn_Plan, Y1–Y4) | B15: =SUMIF(Burn_Plan!$C$5:$R$5,B$6,Burn_Plan!$C$41:$R$41) -> 29.635 | C15: =SUMIF(Burn_Plan!$C$5:$R$5,C$6,Burn_Plan!$C$41:$R$41) -> 47 | D15: =SUMIF(Burn_Plan!$C$5:$R$5,D$6,Burn_Plan!$C$41:$R$41) -> 45.46 | E15: =SUMIF(Burn_Plan!$C$5:$R$5,E$6,Burn_Plan!$C$41:$R$41) -> 38.64 | H15: =SUM(B15:G15) -> 160.735
A16: Stage 3 company operating cost (Y5–Y6, ASSUMED) | B16: 0 | C16: 0 | D16: 0 | E16: 0 | F16: 40 | G16: 40 | H16: =SUM(B16:G16) -> 80 | I16: Company share of Stage 3 run-rate.
A17: Total outflows | B17: =B15+B16 -> 29.635 | C17: =C15+C16 -> 47 | D17: =D15+D16 -> 45.46 | E17: =E15+E16 -> 38.64 | F17: =F15+F16 -> 40 | G17: =G15+G16 -> 40 | H17: =SUM(B17:G17) -> 240.735
A19: Net cash flow | B19: =B13-B17 -> 15.365 | C19: =C13-C17 -> 3 | D19: =D13-D17 -> 13.54 | E19: =E13-E17 -> 61.36 | F19: =F13-F17 -> 30 | G19: =G13-G17 -> 40 | H19: =SUM(B19:G19) -> 163.265
A20: Closing cash (incl. assumed inflows) | B20: =B19 -> 15.365 | C20: =B20+C19 -> 18.365 | D20: =C20+D19 -> 31.905 | E20: =D20+E19 -> 93.265 | F20: =E20+F19 -> 123.265 | G20: =F20+G19 -> 163.265
A21: Closing cash — round only (no revenue) | B21: =B8-B17 -> 15.365 | C21: =B21+C8-C17 -> 13.365 | D21: =C21+D8-D17 -> 12.905 | E21: =D21+E8-E17 -> 19.265 | F21: =E21+F8-F17 -> -20.735 | G21: =F21+G8-G17 -> -60.735 | I21: Round-only cash ignores all assumed revenue; Y5–Y6 shows what Co-Creator cost-share / revenue must cover.

Sheet Returns
A1: Investor Returns — scenario-weighted
A2: Proceeds follow a 1x non-participating liquidation preference (max of preference and as-converted). IRR is a single-cash-flow approximation: MOIC^(1/hold years) − 1.
A4: Scenario | B4: Type | C4: Prob. | D4: Invested (₹ Cr) | E4: Own. at deploy | F4: Own. at exit | G4: Equity value (₹ Cr) | H4: As-converted (₹ Cr) | I4: Preference (₹ Cr) | J4: Proceeds (₹ Cr) | K4: MOIC | L4: Hold (yrs) | M4: IRR ≈ | N4: Prob × proceeds | O4: Prob × invested | P4: PV proceeds | Q4: PV invested | R4: Prob × PV proc. | S4: Prob × PV inv.
A5: =Inputs!A30 -> S1 Co-creation: X becomes the continuity layer in the Co-Creator platform / JV | B5: =Inputs!B30 -> S | C5: =Inputs!C30 -> 0.05 | D5: =SUMIF(Inputs!$H$23:$H$26,"<="&Inputs!F30,Inputs!$E$23:$E$26) -> 180 | E5: =SUMPRODUCT((Inputs!$H$23:$H$26<=Inputs!F30)*Inputs!$E$23:$E$26/Inputs!$I$23:$I$26) -> 0.03 | F5: =E5*(1-Inputs!E30) -> 0.021 | G5: =Inputs!D30 -> 90000 | H5: =F5*G5 -> 1890 | I5: =Inputs!H30*D5 -> 180 | J5: =IF(B5="S",MAX(H5,MIN(I5,G5)),D5*Inputs!I30) -> 1890 | K5: =IF(D5>0,J5/D5,0) -> 10.5 | L5: =Inputs!G30 -> 6 | M5: =IF(K5>0,K5^(1/L5)-1,-1) -> 0.47978362 | N5: =C5*J5 -> 94.5 | O5: =C5*D5 -> 9 | P5: =J5/(1+Inputs!$B$14)^L5 -> 391.56304 | Q5: =SUMPRODUCT((Inputs!$H$23:$H$26<=Inputs!F30)*Inputs!$E$23:$E$26/(1+Inputs!$B$14)^Inputs!$D$23:$D$26) -> 126.72508 | R5: =C5*P5 -> 19.578152 | S5: =C5*Q5 -> 6.336254
A6: =Inputs!A31 -> S2 IP / platform sale or exclusive licence to Co-Creator | B6: =Inputs!B31 -> S | C6: =Inputs!C31 -> 0.1 | D6: =SUMIF(Inputs!$H$23:$H$26,"<="&Inputs!F31,Inputs!$E$23:$E$26) -> 180 | E6: =SUMPRODUCT((Inputs!$H$23:$H$26<=Inputs!F31)*Inputs!$E$23:$E$26/Inputs!$I$23:$I$26) -> 0.03 | F6: =E6*(1-Inputs!E31) -> 0.0255 | G6: =Inputs!D31 -> 30000 | H6: =F6*G6 -> 765 | I6: =Inputs!H31*D6 -> 180 | J6: =IF(B6="S",MAX(H6,MIN(I6,G6)),D6*Inputs!I31) -> 765 | K6: =IF(D6>0,J6/D6,0) -> 4.25 | L6: =Inputs!G31 -> 5 | M6: =IF(K6>0,K6^(1/L6)-1,-1) -> 0.33560423 | N6: =C6*J6 -> 76.5 | O6: =C6*D6 -> 18 | P6: =J6/(1+Inputs!$B$14)^L6 -> 206.03674 | Q6: =SUMPRODUCT((Inputs!$H$23:$H$26<=Inputs!F31)*Inputs!$E$23:$E$26/(1+Inputs!$B$14)^Inputs!$D$23:$D$26) -> 126.72508 | R6: =C6*P6 -> 20.603674 | S6: =C6*Q6 -> 12.672508
A7: =Inputs!A32 -> S3 Partial: non-exclusive licence + team/IP transfer | B7: =Inputs!B32 -> S | C7: =Inputs!C32 -> 0.15 | D7: =SUMIF(Inputs!$H$23:$H$26,"<="&Inputs!F32,Inputs!$E$23:$E$26) -> 180 | E7: =SUMPRODUCT((Inputs!$H$23:$H$26<=Inputs!F32)*Inputs!$E$23:$E$26/Inputs!$I$23:$I$26) -> 0.03 | F7: =E7*(1-Inputs!E32) -> 0.027 | G7: =Inputs!D32 -> 6000 | H7: =F7*G7 -> 162 | I7: =Inputs!H32*D7 -> 180 | J7: =IF(B7="S",MAX(H7,MIN(I7,G7)),D7*Inputs!I32) -> 180 | K7: =IF(D7>0,J7/D7,0) -> 1 | L7: =Inputs!G32 -> 4 | M7: =IF(K7>0,K7^(1/L7)-1,-1) -> 0 | N7: =C7*J7 -> 27 | O7: =C7*D7 -> 27 | P7: =J7/(1+Inputs!$B$14)^L7 -> 63.023003 | Q7: =SUMPRODUCT((Inputs!$H$23:$H$26<=Inputs!F32)*Inputs!$E$23:$E$26/(1+Inputs!$B$14)^Inputs!$D$23:$D$26) -> 126.72508 | R7: =C7*P7 -> 9.4534505 | S7: =C7*Q7 -> 19.008762
A8: =Inputs!A33 -> S4 Stops after Gate 3 not met (T4 never released) | B8: =Inputs!B33 -> F | C8: =Inputs!C33 -> 0.1 | D8: =SUMIF(Inputs!$H$23:$H$26,"<="&Inputs!F33,Inputs!$E$23:$E$26) -> 135 | E8: =SUMPRODUCT((Inputs!$H$23:$H$26<=Inputs!F33)*Inputs!$E$23:$E$26/Inputs!$I$23:$I$26) -> 0.0225 | F8: =E8*(1-Inputs!E33) -> 0.0225 | G8: =Inputs!D33 -> 0 | H8: =F8*G8 -> 0 | I8: =Inputs!H33*D8 -> 135 | J8: =IF(B8="S",MAX(H8,MIN(I8,G8)),D8*Inputs!I33) -> 27 | K8: =IF(D8>0,J8/D8,0) -> 0.2 | L8: =Inputs!G33 -> 3 | M8: =IF(K8>0,K8^(1/L8)-1,-1) -> -0.41519645 | N8: =C8*J8 -> 2.7 | O8: =C8*D8 -> 13.5 | P8: =J8/(1+Inputs!$B$14)^L8 -> 12.289486 | Q8: =SUMPRODUCT((Inputs!$H$23:$H$26<=Inputs!F33)*Inputs!$E$23:$E$26/(1+Inputs!$B$14)^Inputs!$D$23:$D$26) -> 106.2426 | R8: =C8*P8 -> 1.2289486 | S8: =C8*Q8 -> 10.62426
A9: =Inputs!A34 -> S5 Stops at Gate 2 (T3 never released) | B9: =Inputs!B34 -> F | C9: =Inputs!C34 -> 0.25 | D9: =SUMIF(Inputs!$H$23:$H$26,"<="&Inputs!F34,Inputs!$E$23:$E$26) -> 90 | E9: =SUMPRODUCT((Inputs!$H$23:$H$26<=Inputs!F34)*Inputs!$E$23:$E$26/Inputs!$I$23:$I$26) -> 0.015 | F9: =E9*(1-Inputs!E34) -> 0.015 | G9: =Inputs!D34 -> 0 | H9: =F9*G9 -> 0 | I9: =Inputs!H34*D9 -> 90 | J9: =IF(B9="S",MAX(H9,MIN(I9,G9)),D9*Inputs!I34) -> 22.5 | K9: =IF(D9>0,J9/D9,0) -> 0.25 | L9: =Inputs!G34 -> 2 | M9: =IF(K9>0,K9^(1/L9)-1,-1) -> -0.5 | N9: =C9*J9 -> 5.625 | O9: =C9*D9 -> 22.5 | P9: =J9/(1+Inputs!$B$14)^L9 -> 13.313609 | Q9: =SUMPRODUCT((Inputs!$H$23:$H$26<=Inputs!F34)*Inputs!$E$23:$E$26/(1+Inputs!$B$14)^Inputs!$D$23:$D$26) -> 79.615385 | R9: =C9*P9 -> 3.3284024 | S9: =C9*Q9 -> 19.903846
A10: =Inputs!A35 -> S6 Stops at Gate 1 (T2 never released) | B10: =Inputs!B35 -> F | C10: =Inputs!C35 -> 0.35 | D10: =SUMIF(Inputs!$H$23:$H$26,"<="&Inputs!F35,Inputs!$E$23:$E$26) -> 45 | E10: =SUMPRODUCT((Inputs!$H$23:$H$26<=Inputs!F35)*Inputs!$E$23:$E$26/Inputs!$I$23:$I$26) -> 0.0075 | F10: =E10*(1-Inputs!E35) -> 0.0075 | G10: =Inputs!D35 -> 0 | H10: =F10*G10 -> 0 | I10: =Inputs!H35*D10 -> 45 | J10: =IF(B10="S",MAX(H10,MIN(I10,G10)),D10*Inputs!I35) -> 13.5 | K10: =IF(D10>0,J10/D10,0) -> 0.3 | L10: =Inputs!G35 -> 1 | M10: =IF(K10>0,K10^(1/L10)-1,-1) -> -0.7 | N10: =C10*J10 -> 4.725 | O10: =C10*D10 -> 15.75 | P10: =J10/(1+Inputs!$B$14)^L10 -> 10.384615 | Q10: =SUMPRODUCT((Inputs!$H$23:$H$26<=Inputs!F35)*Inputs!$E$23:$E$26/(1+Inputs!$B$14)^Inputs!$D$23:$D$26) -> 45 | R10: =C10*P10 -> 3.6346154 | S10: =C10*Q10 -> 15.75
A11: Probability-weighted totals | C11: =SUM(C5:C10) -> 1 | N11: =SUM(N5:N10) -> 211.05 | O11: =SUM(O5:O10) -> 105.75 | R11: =SUM(R5:R10) -> 57.827243 | S11: =SUM(S5:S10) -> 84.29563
A13: Headline outputs
A14: Best-case MOIC (S1) | D14: =MAX(K5:K10) -> 10.5
A15: Expected proceeds (₹ Cr, prob-weighted) | D15: =N11 -> 211.05
A16: Expected capital deployed (₹ Cr, prob-weighted) | D16: =O11 -> 105.75
A17: Expected MOIC = E[proceeds] ÷ E[invested] | D17: =IF(O11>0,N11/O11,0) -> 1.9957447 | F17: Expected MOIC > 1.0x means the price is supportable on the stated odds; investors will substitute their own.
A18: Hurdle-adjusted profitability index (PV proceeds ÷ PV invested) | D18: =IF(S11>0,R11/S11,0) -> 0.68600523
A19: Probability of ≥ 1.0x (capital returned) | D19: =SUMPRODUCT(C5:C10*(K5:K10>=1)) -> 0.3
A20: Probability of ≥ 3.0x | D20: =SUMPRODUCT(C5:C10*(K5:K10>=3)) -> 0.15
A21: Probability of ≥ 10.0x | D21: =SUMPRODUCT(C5:C10*(K5:K10>=10)) -> 0.05
A22: Probability of capital loss (< 1.0x) | D22: =SUMPRODUCT(C5:C10*(K5:K10<1)) -> 0.7
A23: Maximum capital at risk if Gate 1 fails (₹ Cr) | D23: =D10*(1-Inputs!I35) -> 31.5
A25: What exit value is needed? (equity value ₹ Cr for full ₹180 Cr invested, by target MOIC and additional dilution before exit)
A26: Target MOIC | C26: Dil. 0% | D26: Dil. 15% | E26: Dil. 30% | F26: Dil. 45%
A27: Additional dilution before exit → | C27: 0 | D27: 0.15 | E27: 0.3 | F27: 0.45
A28: 1 | C28: =$A28*Inputs!$B$7/(1-C$27) -> 6000 | D28: =$A28*Inputs!$B$7/(1-D$27) -> 7058.8235 | E28: =$A28*Inputs!$B$7/(1-E$27) -> 8571.4286 | F28: =$A28*Inputs!$B$7/(1-F$27) -> 10909.091
A29: 3 | C29: =$A29*Inputs!$B$7/(1-C$27) -> 18000 | D29: =$A29*Inputs!$B$7/(1-D$27) -> 21176.471 | E29: =$A29*Inputs!$B$7/(1-E$27) -> 25714.286 | F29: =$A29*Inputs!$B$7/(1-F$27) -> 32727.273
A30: 5 | C30: =$A30*Inputs!$B$7/(1-C$27) -> 30000 | D30: =$A30*Inputs!$B$7/(1-D$27) -> 35294.118 | E30: =$A30*Inputs!$B$7/(1-E$27) -> 42857.143 | F30: =$A30*Inputs!$B$7/(1-F$27) -> 54545.455
A31: 10 | C31: =$A31*Inputs!$B$7/(1-C$27) -> 60000 | D31: =$A31*Inputs!$B$7/(1-D$27) -> 70588.235 | E31: =$A31*Inputs!$B$7/(1-E$27) -> 85714.286 | F31: =$A31*Inputs!$B$7/(1-F$27) -> 109090.91
A32: 20 | C32: =$A32*Inputs!$B$7/(1-C$27) -> 120000 | D32: =$A32*Inputs!$B$7/(1-D$27) -> 141176.47 | E32: =$A32*Inputs!$B$7/(1-E$27) -> 171428.57 | F32: =$A32*Inputs!$B$7/(1-F$27) -> 218181.82
A34: Same, in US$ billion
A35: =A28 -> 1 | C35: =C28/(Inputs!$B$6*100) -> 0.66666667 | D35: =D28/(Inputs!$B$6*100) -> 0.78431373 | E35: =E28/(Inputs!$B$6*100) -> 0.95238095 | F35: =F28/(Inputs!$B$6*100) -> 1.2121212
A36: =A29 -> 3 | C36: =C29/(Inputs!$B$6*100) -> 2 | D36: =D29/(Inputs!$B$6*100) -> 2.3529412 | E36: =E29/(Inputs!$B$6*100) -> 2.8571429 | F36: =F29/(Inputs!$B$6*100) -> 3.6363636
A37: =A30 -> 5 | C37: =C30/(Inputs!$B$6*100) -> 3.3333333 | D37: =D30/(Inputs!$B$6*100) -> 3.9215686 | E37: =E30/(Inputs!$B$6*100) -> 4.7619048 | F37: =F30/(Inputs!$B$6*100) -> 6.0606061
A38: =A31 -> 10 | C38: =C31/(Inputs!$B$6*100) -> 6.6666667 | D38: =D31/(Inputs!$B$6*100) -> 7.8431373 | E38: =E31/(Inputs!$B$6*100) -> 9.5238095 | F38: =F31/(Inputs!$B$6*100) -> 12.121212
A39: =A32 -> 20 | C39: =C32/(Inputs!$B$6*100) -> 13.333333 | D39: =D32/(Inputs!$B$6*100) -> 15.686275 | E39: =E32/(Inputs!$B$6*100) -> 19.047619 | F39: =F32/(Inputs!$B$6*100) -> 24.242424
A41: Sensitivity — how the answer changes with the post-money price (proceeds ₹ Cr by scenario; same odds)
A42: Post-money (₹ Cr) → | C42: 3000 | D42: 4500 | E42: 6000 | F42: 7500 | G42: 9000 | H42: 12000
A43: =Inputs!A30 -> S1 Co-creation: X becomes the continuity layer in the Co-Creator platform / JV | C43: =IF($B5="S",MAX($D5/C$42*(1-Inputs!$E30)*$G5,MIN($I5,$G5)),$D5*Inputs!$I30) -> 3780 | D43: =IF($B5="S",MAX($D5/D$42*(1-Inputs!$E30)*$G5,MIN($I5,$G5)),$D5*Inputs!$I30) -> 2520 | E43: =IF($B5="S",MAX($D5/E$42*(1-Inputs!$E30)*$G5,MIN($I5,$G5)),$D5*Inputs!$I30) -> 1890 | F43: =IF($B5="S",MAX($D5/F$42*(1-Inputs!$E30)*$G5,MIN($I5,$G5)),$D5*Inputs!$I30) -> 1512 | G43: =IF($B5="S",MAX($D5/G$42*(1-Inputs!$E30)*$G5,MIN($I5,$G5)),$D5*Inputs!$I30) -> 1260 | H43: =IF($B5="S",MAX($D5/H$42*(1-Inputs!$E30)*$G5,MIN($I5,$G5)),$D5*Inputs!$I30) -> 945
A44: =Inputs!A31 -> S2 IP / platform sale or exclusive licence to Co-Creator | C44: =IF($B6="S",MAX($D6/C$42*(1-Inputs!$E31)*$G6,MIN($I6,$G6)),$D6*Inputs!$I31) -> 1530 | D44: =IF($B6="S",MAX($D6/D$42*(1-Inputs!$E31)*$G6,MIN($I6,$G6)),$D6*Inputs!$I31) -> 1020 | E44: =IF($B6="S",MAX($D6/E$42*(1-Inputs!$E31)*$G6,MIN($I6,$G6)),$D6*Inputs!$I31) -> 765 | F44: =IF($B6="S",MAX($D6/F$42*(1-Inputs!$E31)*$G6,MIN($I6,$G6)),$D6*Inputs!$I31) -> 612 | G44: =IF($B6="S",MAX($D6/G$42*(1-Inputs!$E31)*$G6,MIN($I6,$G6)),$D6*Inputs!$I31) -> 510 | H44: =IF($B6="S",MAX($D6/H$42*(1-Inputs!$E31)*$G6,MIN($I6,$G6)),$D6*Inputs!$I31) -> 382.5
A45: =Inputs!A32 -> S3 Partial: non-exclusive licence + team/IP transfer | C45: =IF($B7="S",MAX($D7/C$42*(1-Inputs!$E32)*$G7,MIN($I7,$G7)),$D7*Inputs!$I32) -> 324 | D45: =IF($B7="S",MAX($D7/D$42*(1-Inputs!$E32)*$G7,MIN($I7,$G7)),$D7*Inputs!$I32) -> 216 | E45: =IF($B7="S",MAX($D7/E$42*(1-Inputs!$E32)*$G7,MIN($I7,$G7)),$D7*Inputs!$I32) -> 180 | F45: =IF($B7="S",MAX($D7/F$42*(1-Inputs!$E32)*$G7,MIN($I7,$G7)),$D7*Inputs!$I32) -> 180 | G45: =IF($B7="S",MAX($D7/G$42*(1-Inputs!$E32)*$G7,MIN($I7,$G7)),$D7*Inputs!$I32) -> 180 | H45: =IF($B7="S",MAX($D7/H$42*(1-Inputs!$E32)*$G7,MIN($I7,$G7)),$D7*Inputs!$I32) -> 180
...

Sheet Valuation
A1: Valuation Credibility — four lenses
A2: Comparables are press-reported (confidence noted), not company-confirmed. Re-verify before sharing externally.
A4: Lens 1 — Market precedents (AI)
A5: Reference | B5: Type | C5: US$ bn | D5: Date | E5: ₹ Cr | F5: Our post-money ÷ ref. | G5: Confidence | H5: Source
A6: Safe Superintelligence (SSI) | B6: Pre-product valuation | C6: 32 | D6: Apr 2025 | E6: =C6*Inputs!$B$6*100 -> 288000 | F6: =Inputs!$B$7/E6 -> 0.020833333 | G6: Medium-High | H6: https://www.maginative.com/article/sutskevers-safe-superintelligence-raises-another-2b-at-32b-valuation//
A7: Sarvam AI (India sovereign LLM) | B7: Series B valuation | C7: 1.5 | D7: Jun 2026 | E7: =C7*Inputs!$B$6*100 -> 13500 | F7: =Inputs!$B$7/E7 -> 0.44444444 | G7: Medium | H7: https://www.exchange4media.com/industry-briefing-news/sarvam-raises-234m-in-first-close-of-300m-series-b-at-15b-valuation-155498.html
A8: Microsoft–Inflection | B8: Licence + hire | C8: 0.65 | D8: Mar 2024 | E8: =C8*Inputs!$B$6*100 -> 5850 | F8: =Inputs!$B$7/E8 -> 1.025641 | G8: Medium | H8: https://www.implicator.ai/nvidias-20-billion-groq-deal-perfects-silicon-valleys-favorite-antitrust-dodge/
A9: Google–Character.AI | B9: Licence + hire | C9: 2.7 | D9: Aug 2024 | E9: =C9*Inputs!$B$6*100 -> 24300 | F9: =Inputs!$B$7/E9 -> 0.24691358 | G9: Medium | H9: https://www.implicator.ai/nvidias-20-billion-groq-deal-perfects-silicon-valleys-favorite-antitrust-dodge/
A10: Nvidia–Groq | B10: Licence + hire | C10: 20 | D10: Dec 2025 | E10: =C10*Inputs!$B$6*100 -> 180000 | F10: =Inputs!$B$7/E10 -> 0.033333333 | G10: Medium | H10: https://www.implicator.ai/nvidias-20-billion-groq-deal-perfects-silicon-valleys-favorite-antitrust-dodge/
A11: Meta–Scale AI | B11: Investment + hire (stake) | C11: 14.3 | D11: 2025 | E11: =C11*Inputs!$B$6*100 -> 128700 | F11: =Inputs!$B$7/E11 -> 0.046620047 | G11: Medium | H11: https://www.implicator.ai/nvidias-20-billion-groq-deal-perfects-silicon-valleys-favorite-antitrust-dodge/
A12: Indian peer set note: identity/continuity-layer and AI-memory comparables not yet sourced — add before external use.
A14: Scenario values vs the nearest precedent
A15: Scenario | B15: Equity value (₹ Cr) | C15: US$ bn | E15: Nearest precedent | F15: Scenario ÷ precedent
A16: =Returns!A5 -> S1 Co-creation: X becomes the continuity layer in the Co-Creator platform / JV | B16: =Returns!G5 -> 90000 | C16: =B16/(Inputs!$B$6*100) -> 10 | E16: =A6 -> Safe Superintelligence (SSI) | F16: =B16/E6 -> 0.3125
A17: =Returns!A6 -> S2 IP / platform sale or exclusive licence to Co-Creator | B17: =Returns!G6 -> 30000 | C17: =B17/(Inputs!$B$6*100) -> 3.3333333 | E17: =A9 -> Google–Character.AI | F17: =B17/E9 -> 1.2345679
A18: =Returns!A7 -> S3 Partial: non-exclusive licence + team/IP transfer | B18: =Returns!G7 -> 6000 | C18: =B18/(Inputs!$B$6*100) -> 0.66666667 | E18: =A8 -> Microsoft–Inflection | F18: =B18/E8 -> 1.025641
A20: Lens 2 — Expected value at the investor’s own hurdle (from Returns)
A21: Expected MOIC | B21: =Returns!D17 -> 1.9957447
A22: Hurdle-adjusted profitability index (>1.0x supports the price) | B22: =Returns!D18 -> 0.68600523
A23: Probability capital is returned (≥1.0x) | B23: =Returns!D19 -> 0.3
A24: Best-case MOIC | B24: =Returns!D14 -> 10.5
A26: Lens 3 — Structure earns the price: capital at risk by stage gate
A27: If the venture stops at… | B27: Capital deployed (₹ Cr) | C27: % of round | D27: Recovery % | E27: Recovered (₹ Cr) | F27: Net loss (₹ Cr) | G27: % of round lost
A28: Gate 1 (after T1) | B28: =Returns!D10 -> 45 | C28: =B28/Inputs!$B$8 -> 0.25 | D28: =Inputs!I35 -> 0.3 | E28: =B28*D28 -> 13.5 | F28: =B28-E28 -> 31.5 | G28: =F28/Inputs!$B$8 -> 0.175
A29: Gate 2 (after T2) | B29: =Returns!D9 -> 90 | C29: =B29/Inputs!$B$8 -> 0.5 | D29: =Inputs!I34 -> 0.25 | E29: =B29*D29 -> 22.5 | F29: =B29-E29 -> 67.5 | G29: =F29/Inputs!$B$8 -> 0.375
A30: Gate 3 (after T3) | B30: =Returns!D8 -> 135 | C30: =B30/Inputs!$B$8 -> 0.75 | D30: =Inputs!I33 -> 0.2 | E30: =B30*D30 -> 27 | F30: =B30-E30 -> 108 | G30: =F30/Inputs!$B$8 -> 0.6
A32: Without tranching, a failure at Gate 1 would put the full round at risk; with tranching only T1 is.
A34: Lens 4 — Unit economics of the ticket
A35: Price of 1% (₹ Cr) | B35: =Inputs!B11 -> 60
A36: Post-money (US$ mn) | B36: =Inputs!B12 -> 666.66667
A37: Round (US$ mn) | B37: =Inputs!B13 -> 20
A38: Round as % of Sarvam AI valuation (round ÷ ref.) | B38: =Inputs!B8/E7 -> 0.013333333
A39: Post-money as % of Sarvam AI valuation | B39: =Inputs!B7/E7 -> 0.44444444
A41: Narrative use: post-money is a fraction of India’s leading sovereign-AI peer, priced as a milestone-gated option on a new infrastructure layer — not as a revenue multiple.

Sheet Truthiness_Ledger
A1: Truthiness Ledger — claims calibrated per the Canon
A2: States below are PROPOSED by the model author for founder confirmation. Canon test: Evidence · Interpretation · Limit · Counter-Lens · Falsifier · Update.
A4: # | B4: Claim made to investors | C4: Proposed state | D4: Evidence today / basis | E4: Limit (what cannot yet be seen) | F4: Strongest counter-lens | G4: Falsifier (what would prove us wrong) | H4: Resolved by
A5: 1 | B5: AI is making capability (knowledge, language, reasoning, execution) abundant; advantage shifts toward judgment and continuity. | C5: INFERRED | D5: Widely observed model commoditisation (Canon Act I). | E5: Whether buyers will pay for a continuity layer rather than get it free from model vendors. | F5: Model vendors bundle memory/identity for free and lock it in. | G5: Pilots show no willingness to pay for portability/governance. | H5: Gate 2
A6: 2 | B6: Models, sessions and vendors reset: users and enterprises lack governed, portable cognitive continuity. | C6: INFERRED | D6: Canon Act V; to be validated by customer interviews. | E6: Degree of pain across segments. | F6: Vendor-native memory is "good enough". | G6: Design partners decline to pilot. | H6: Gate 1–2
A7: 3 | B7: Portable Cognitive Identity can be specified as a structured, permissioned, evolvable representation (8 layers) independent of any model. | C7: ASSUMED | D7: Canon slides 65–74 define it; no reference implementation shown in the extract. | E7: Technical feasibility at quality across model families. | F7: Representation is too lossy or model-specific to travel. | G7: Handshake fails to preserve judgment across ≥3 model families. | H7: Gate 1
A8: 4 | B8: Interpretive Calibration (separating fact from inference, matching confidence to resolution) improves outcomes vs baseline. | C8: ASSUMED | D8: Conceptual (Canon slide 52). | E8: No benchmark yet. | F8: Gains vanish against strong prompting / RAG baselines. | G8: Independent benchmark shows no significant lift. | H8: Gate 1
A9: 5 | B9: Enterprises / governments will pay for governed continuity and permissioned portability. | C9: ASSUMED | D9: None yet. | E9: Willingness to pay, procurement cycle. | F9: Treated as a feature, not a product. | G9: No paid pilots by Gate 2. | H9: Gate 2
A10: 6 | B10: Privacy and data-portability regulation (e.g. India DPDP Act 2023 and Rules) favours permissioned, revocable, user-owned continuity. | C10: INFERRED | D10: Statute exists; fit to X design to be confirmed by counsel. | E10: Final Rules, enforcement, cross-border effects. | F10: Compliance burden favours incumbents. | G10: Counsel finds design conflicts with obligations. | H10: Gate 1 (legal opinion)
A11: 7 | B11: A Co-Creator (frontier lab, hyperscaler, device OEM or sovereign programme) will co-build or acquire. | C11: UNCERTAIN | D11: Licence-and-hire precedents exist (press-reported). | E11: No counterparty engaged. | F11: Co-creators build in-house. | G11: No LOI by Gate 2. | H11: Gate 2–3
A12: 8 | B12: ₹6,000 Cr post-money is supportable for Round 1. | C12: DISPUTED | D12: Comparables are far larger companies with products or revenue; value rests on option logic and structure. | E12: Investor’s own probabilities. | F12: Pre-revenue; market may price at a fraction. | G12: Syndicate fails to form at this price even with tranching and preference. | H12: Round close
A13: 9 | B13: The long-horizon "Super Intellect" outcome (systems that examine their own frame) is reachable with a Co-Creator. | C13: ASSUMED | D13: Canon: Intellect governs capability (slides 41–46). | E13: Technical path undefined. | F13: Remains a concept for a decade. | G13: No measurable progress on self-frame-examination by Gate 3. | H13: Stage 3
A14: 10 | B14: Quantum computing makes intellect "dynamic" and accelerates the path. | C14: UNCERTAIN | D14: Not in the Canon extract. | E14: No evidence connecting it to Stages 1–2. | F14: Irrelevant to near-term product. | G14: No identified quantum-dependent milestone by Gate 2. | H14: Stage 3 option only
A15: 11 | B15: IP is defensible through specification, patents and standards position. | C15: UNCERTAIN | D15: No filings referenced. | E15: Freedom-to-operate, prior art. | F15: Concept-level claims are hard to patent. | G15: Patent search shows prior art covering core claims. | H15: Gate 1
A16: 12 | B16: The team can execute the plan within ₹180 Cr. | C16: ASSUMED | D16: Plan proposed in Burn_Plan. | E16: Hiring, retention. | F16: Talent cost inflation. | G16: Hiring plan misses by >1 quarter at Gate 1. | H16: Gate 1

Sheet Checks
A1: Model Integrity Checks
A2: All rows must read OK before sharing.
A4: Check | B4: Value | C4: Status
A5: Pre-money + round = post-money | B5: =Inputs!B9+Inputs!B8-Inputs!B7 -> 0 | C5: =IF(ABS(B5)<0.001,"OK","CHECK") -> OK
A6: Tranche percentages sum to 100% | B6: =Inputs!B27 -> 1 | C6: =IF(ABS(B6-1)<0.0001,"OK","CHECK") -> OK
A7: Scenario probabilities sum to 100% | B7: =Inputs!C36 -> 1 | C7: =IF(ABS(B7-1)<0.0001,"OK","CHECK") -> OK
A8: Syndicate tickets equal round size | B8: =Round_CapTable!B19-Inputs!B8 -> 0 | C8: =IF(ABS(B8)<0.001,"OK","CHECK") -> OK
A9: Pre-round ownership sums to 100% | B9: =Round_CapTable!B9 -> 1 | C9: =IF(ABS(B9-1)<0.0001,"OK","CHECK") -> OK
A10: Post-round ownership sums to 100% | B10: =Round_CapTable!C9 -> 1 | C10: =IF(ABS(B10-1)<0.0001,"OK","CHECK") -> OK
A11: Use of funds total equals round size | B11: =Use_of_Funds!B18-Inputs!B8 -> 0 | C11: =IF(ABS(B11)<0.001,"OK","CHECK") -> OK
A12: Reserve ≥ policy floor | B12: =Use_of_Funds!C17 -> 0.10702778 | C12: =IF(B12>=Inputs!B15,"OK","CHECK") -> OK
A13: Cash from round never negative (min closing cash, ₹ Cr) | B13: =MIN(Burn_Plan!C46:R46) -> 12.905 | C13: =IF(B13>=0,"OK","CHECK") -> OK
A14: Year-1 spend funded by T1 (T1 − Y1 spend, ₹ Cr) | B14: =Inputs!E23-Stage_Plan!B15 -> 15.365 | C14: =IF(B14>=0,"OK","CHECK") -> OK
A15: Closing cash Q16 equals reserve less founder allocation (diff) | B15: =Burn_Plan!R46-(Use_of_Funds!B17) -> 0 | C15: =IF(ABS(B15)<0.001,"OK","CHECK") -> OK
A16: Cumulative spend reconciles to Use_of_Funds programme lines (diff) | B16: =Burn_Plan!R47-SUM(Use_of_Funds!B5:B15) -> 0 | C16: =IF(ABS(B16)<0.001,"OK","CHECK") -> OK
A18: OVERALL | C18: =IF(COUNTIF(C5:C16,"OK")=12,"ALL OK","REVIEW") -> ALL OK
